Workbook
Name MF_LatestAUMCol: MATCH("Net Assets Under Management as on March 31, 2026 (INR in crore)",'AMFI-Mar''25 to Mar''26'!$3:$3,0)
Name MF_NetFlowCol: MATCH("Net Inflow (+ve)/Outflow (-ve) for the month of March 2026 (INR in crore)",'AMFI-Mar''25 to Mar''26'!$3:$3,0)
Name MF_RedemptionCol: MATCH("Repurchase/Redemption for the month of March 2026 (INR in crore)",'AMFI-Mar''25 to Mar''26'!$3:$3,0)
Name MF_SalesCol: MATCH("Funds Mobilized for the month of March 2026 (INR in crore)",'AMFI-Mar''25 to Mar''26'!$3:$3,0)

Sheet AMFI-SIP
A1: SIP Contribution
A2: Month-wise SIP contribution collected from FY 2016-17 onwards are mentioned below:
A3: Month | C3: SIP Contribution ₹ Crore
A4: Fig in cr | B4: FY 2026-27 | C4: FY 2025-26 | D4: FY 2024-25 | E4: FY 2023-24 | F4: FY 2022-23 | G4: FY 2021-22 | H4: FY 2020-21 | I4: FY 2019-20 | J4: FY 2018-19 | K4: FY 2017-18 | L4: FY 2016-17
A5: Total During FY | B5: =SUBTOTAL(9,B6:B17) | C5: =SUBTOTAL(9,C6:C17) | D5: =SUBTOTAL(9,D6:D17) | E5: =SUBTOTAL(9,E6:E17) | F5: =SUBTOTAL(9,F6:F17) | G5: =SUBTOTAL(9,G6:G17) | H5: =SUBTOTAL(9,H6:H17) | I5: =SUBTOTAL(9,I6:I17) | ... L5: =SUBTOTAL(9,L6:L17)
A6: March | C6: 32087 | D6: 25926 | E6: 19271 | F6: 14276 | G6: 12328 | H6: 9182 | I6: 8641 | J6: 8055 | K6: 7119 | L6: 4335
A7: February | C7: 29845 | D7: 25999 | E7: 19187 | F7: 13686 | G7: 11438 | H7: 7528 | I7: 8513 | J7: 8095 | K7: 6425 | L7: 4050
A8: January | C8: 31002 | D8: 26400 | E8: 18838 | F8: 13856 | G8: 11517 | H8: 8023 | I8: 8532 | J8: 8064 | K8: 6644 | L8: 4095
A9: December | C9: 31002 | D9: 26459 | E9: 17610 | F9: 13573 | G9: 11305 | H9: 8418 | I9: 8518 | J9: 8022 | K9: 6222 | L9: 3973
A10: November | C10: 29445 | D10: 25320 | E10: 17073 | F10: 13306 | G10: 11005 | H10: 7302 | I10: 8273 | J10: 7985 | K10: 5893 | L10: 3884
A11: October | C11: 29529 | D11: 25323 | E11: 16928 | F11: 13041 | G11: 10519 | H11: 7800 | I11: 8246 | J11: 7985 | K11: 5621 | L11: 3434
A12: September | C12: 29361 | D12: 24509 | E12: 16042 | F12: 12976 | G12: 10351 | H12: 7788 | I12: 8263 | J12: 7727 | K12: 5516 | L12: 3698
A13: August | C13: 28265 | D13: 23547 | E13: 15814 | F13: 12693 | G13: 9923 | H13: 7792 | I13: 8231 | J13: 7658 | K13: 5206 | L13: 3497
A14: July | C14: 28464 | D14: 23332 | E14: 15245 | F14: 12140 | G14: 9609 | H14: 7831 | I14: 8324 | J14: 7554 | K14: 4947 | L14: 3334
A15: Jun | C15: 27269 | D15: 21262 | E15: 14734 | F15: 12276 | G15: 9156 | H15: 7917 | I15: 8122 | J15: 7554 | K15: 4744 | L15: 3310
A16: May | C16: 26688 | D16: 20904 | E16: 14749 | F16: 12286 | G16: 8819 | H16: 8123 | I16: 8183 | J16: 7304 | K16: 4584 | L16: 3189
A17: April | B17: 31115 | C17: 26632 | D17: 20371 | E17: 13728 | F17: 11863 | G17: 8596 | H17: 8376 | I17: 8238 | J17: 6690 | K17: 4269 | L17: 3122
A19: SIP Count -
A20: - | B20: (Lakh) | C20: (Lakh) | D20: (Lakh) | E20: (Lakh) | F20: (Cr) | G20: (Cr)
A21: Month | B21: Total No. of outstanding SIP Accounts | C21: No. of New SIPs registered | D21: No. of SIPs discontinued*/tenure completed | E21: No. of Contributing SIP accounts | F21: SIP Contribution ₹ crore | G21: SIP AUM ₹ crore
A22: 46113 | B22: 1044.26 | C22: 50.71 | D22: 51.29 | E22: 964.91 | F22: 31115 | G22: 1685126
A24: Apr 25 – Mar 26 | B24: =B25 | C24: =SUM(C25:C36) | D24: =SUM(D25:D36) | E24: =E25 | F24: =SUM(F25:F36) | G24: =G25
A25: 46082 | B25: 1044.84 | C25: 52.82 | D25: 53.38 | E25: 971.86 | F25: 32087 | G25: 1510943
A26: 46054 | B26: 1045.4 | C26: 65.72 | D26: 49.7 | E26: 944.48 | F26: 29845 | G26: 1664085
A27: 46023 | B27: 1029.38 | C27: 74.11 | D27: 55.46 | E27: 992.19 | F27: 31002 | G27: 1636082
A28: 45992 | B28: 1010.73 | C28: 60.46 | D28: 51.57 | E28: 979 | F28: 31002 | G28: 1663369
A29: 45962 | B29: 1001.84 | C29: 57.14 | D29: 43.18 | E29: 942.52 | F29: 29445 | G29: 1652665
A30: 45931 | B30: 987.88 | C30: 60.25 | D30: 45.1 | E30: 945.2 | F30: 29529 | G30: 1625305
A31: 45901 | B31: 972.74 | C31: 57.73 | D31: 44.03 | E31: 925.21 | F31: 29361 | G31: 1552303
A32: 45870 | B32: 959.04 | C32: 55.23 | D32: 41.15 | E32: 898.7 | F32: 28265 | G32: 1518368
A33: 45839 | B33: 944.97 | C33: 68.69 | D33: 43.04 | E33: 911.18 | F33: 28464 | G33: 1519456
A34: 45809 | B34: 919.32 | C34: 61.91 | D34: 48.16 | E34: 864.7 | F34: 27269 | G34: 1530574
A35: 45778 | B35: 905.57 | C35: 59.15 | D35: 42.66 | E35: 856 | F35: 26688 | G35: 1461360
A36: 45748 | B36: 889.08 | C36: 46.01 | D36: 162.32 | E36: 838.25 | F36: 26632 | G36: 1389655
A37: Apr 24 – Mar 25 | B37: 1005.39 | C37: 679.85 | D37: 514.17 | E37: 811.16 | F37: 289352 | G37: 1335188
A39: Apr 23 – Mar 24 | B39: 839.71 | C39: 428.09 | D39: 224.37 | E39: - | F39: 199219 | G39: 1071666
A41: * As per SEBI guidelines, the SIPs where
A42: - 3 consecutive instalments with respect to daily, weekly, fortnightly, and monthly intervals and
A43: - 2 consecutive instalments with respect to others are failed, are treated as ceased/discontinued.
A44: # Includes the past/legacy data on account of above reason, revised on 14th May 2025.

Sheet AMFI-Mar'25 to Mar'26
P1: - | Z1: - | AJ1: - | AT1: - | BD1: - | BN1: - | BX1: - | CH1: - | CR1: - | DB1: - | DL1: - | DO1: - | EB1: - | EE1: - | EI1: - | ES1: - | EV1: -
A2: - | B2: - | C2: - | D2: - | E2: - | G2: Mar'25 | P2: - | Q2: Apr'25 | Z2: - | AA2: May'25 | AJ2: - | AK2: Jun'25 | AT2: - | AU2: Jul'25 | BD2: - | BE2: Aug'25 | BN2: - | BO2: Sep'25 | BX2: - | BY2: Oct'25 | CH2: - | CI2: Nov'25 | CR2: - | CS2: Dec'25 | DB2: - | DC2: Jan'25 | DL2: - | DM2: Apr'25 to Jan'26 | DO2: - | DP2: - | DQ2: - | DR2: - | DS2: Feb'26 | EB2: - | EC2: Apr'25 to Feb'26 | EE2: - | EF2: - | EG2: - | EH2: - | EI2: - | EJ2: Mar'26 | ES2: - | ET2: Apr'25 to Mar'26 | EV2: - | EW2: - | EX2: - | EY2: -
A3: Scheme Name | B3: AMFI-Asset Type | C3: AMFI-Open ended Schemes/Closed ended Schemes | D3: DEBT / EQUITY | E3: SALES_PROD_MIS | F3: Fund Type | G3: No. of Schemes as on March 31, 2025 | H3: No. of Folios as on March 31, 2025 | I3: Funds Mobilized for the month of March 2025 (INR in crore) | J3: Repurchase/ Redemption for the month of March 2025 (INR in crore) | K3: Net Inflow (+ve)/Outflow (-ve) for the month of March 2025 (INR in crore) | L3: Net Assets Under Management as on March 31, 2025 (INR in crore) | M3: Average Net Assets Under Management for the month March 2025 (INR in crore) | N3: No. of segregated portfolios created as on March 31, 2025 | O3: Net Assets Under Management in segregated portfolio as on March 31, 2025 (INR in crore) | P3: - | Q3: No. of Schemes as on April 30, 2025 | R3: No. of Folios as on April 30, 2025 | S3: Funds Mobilized for the month of April 2025 (INR in crore) | T3: Repurchase/ Redemption for the month of April 2025 (INR in crore) | U3: Net Inflow (+ve)/Outflow (-ve) for the month of April 2025 (INR in crore) | V3: Net Assets Under Management as on April 30, 2025 (INR in crore) | W3: Average Net Assets Under Management for the month April 2025 (INR in crore) | X3: No. of segregated portfolios created as on April 30, 2025 | Y3: Net Assets Under Management in segregated portfolio as on April 30, 2025 (INR in crore) | Z3: - | AA3: No. of Schemes as on May 31, 2025 | AB3: No. of Folios as on May 31, 2025 | AC3: Funds Mobilized for the month of May 2025 (INR in crore) | AD3: Repurchase/ Redemption for the month of May 2025 (INR in crore) | AE3: Net Inflow (+ve)/Outflow (-ve) for the month of May 2025 (INR in crore) | AF3: Net Assets Under Management as on May 31, 2025 (INR in crore) | AG3: Average Net Assets Under Management for the month May 2025 (INR in crore) | AH3: No. of segregated portfolios created as on May 31, 2025 | AI3: Net Assets Under Management in segregated portfolio as on May 31, 2025 (INR in crore) | AJ3: - | AK3: No. of Schemes as on June 30, 2025 | AL3: No. of Folios as on June 30, 2025 | AM3: Funds Mobilized for the month of June 2025 (INR in crore) | AN3: Repurchase/ Redemption for the month of June 2025 (INR in crore) | AO3: Net Inflow (+ve)/Outflow (-ve) for the month of June 2025 (INR in crore) | AP3: Net Assets Under Management as on June 30, 2025 (INR in crore) | AQ3: Average Net Assets Under Management for the month June 2025 (INR in crore) | AR3: No. of segregated portfolios created as on June 30, 2025 | AS3: Net Assets Under Management in segregated portfolio as on June 30, 2025 (INR in crore) | AT3: - | AU3: No. of Schemes as on July 31, 2025 | AV3: No. of Folios as on July 31, 2025 | AW3: Funds Mobilized for the month of July 2025 (INR in crore) | AX3: Repurchase/Redemption for the month of July 2025 (INR in crore) | AY3: Net Inflow (+ve)/Outflow (-ve) for the month of July 2025 (INR in crore) | AZ3: Net Assets Under Management as on July 31, 2025 (INR in crore) | BA3: Average Net Assets Under Management for the month July 2025 (INR in crore) | BB3: No. of segregated portfolios created as on July 31, 2025 | BC3: Net Assets Under Management in segregated portfolio as on July 31, 2025 (INR in crore) | BD3: - | BE3: No. of Schemes as on August 31, 2025 | BF3: No. of Folios as on August 31, 2025 | BG3: Funds Mobilized for the month of August 2025 (INR in crore) | BH3: Repurchase/Redemption for the month of August 2025 (INR in crore) | BI3: Net Inflow (+ve)/Outflow (-ve) for the month of August 2025 (INR in crore) | BJ3: Net Assets Under Management as on August 31, 2025 (INR in crore) | BK3: Average Net Assets Under Management for the month August 2025 (INR in crore) | BL3: No. of segregated portfolios created as on August 31, 2025 | BM3: Net Assets Under Management in segregated portfolio as on August 31, 2025 (INR in crore) | BN3: - | BO3: No. of Schemes as on September 30, 2025 | BP3: No. of Folios as on September 30, 2025 | BQ3: Funds Mobilized for the month of September 2025 (INR in crore) | BR3: Repurchase/Redemption for the month of September 2025 (INR in crore) | BS3: Net Inflow (+ve)/Outflow (-ve) for the month of September 2025 (INR in crore) | BT3: Net Assets Under Management as on September 30, 2025 (INR in crore) | BU3: Average Net Assets Under Management for the month September 2025 (INR in crore) | BV3: No. of segregated portfolios created as on September 30, 2025 | BW3: Net Assets Under Management in segregated portfolio as on September 30, 2025 (INR in crore) | BX3: - | BY3: No. of Schemes as on October 31, 2025 | BZ3: No. of Folios as on October 31, 2025 | CA3: Funds Mobilized for the month of October 2025 (INR in crore) | CB3: Repurchase/Redemption for the month of October 2025 (INR in crore) | CC3: Net Inflow (+ve)/Outflow (-ve) for the month of October 2025 (INR in crore) | CD3: Net Assets Under Management as on October 31, 2025 (INR in crore) | CE3: Average Net Assets Under Management for the month October 2025 (INR in crore) | CF3: No. of segregated portfolios created as on October 31, 2025 | CG3: Net Assets Under Management in segregated portfolio as on October 31, 2025 (INR in crore) | CH3: - | CI3: No. of Schemes as on November 30, 2025 | CJ3: No. of Folios as on November 30, 2025 | CK3: Funds Mobilized for the month of November 2025 (INR in crore) | CL3: Repurchase/Redemption for the month of November 2025 (INR in crore) | CM3: Net Inflow (+ve)/Outflow (-ve) for the month of November 2025 (INR in crore) | CN3: Net Assets Under Management as on November 30, 2025 (INR in crore) | CO3: Average Net Assets Under Management for the month November 2025 (INR in crore) | CP3: No. of segregated portfolios created as on November 30, 2025 | CQ3: Net Assets Under Management in segregated portfolio as on November 30, 2025 (INR in crore) | CR3: - | CS3: No. of Schemes as on December 31, 2025 | CT3: No. of Folios as on December 31, 2025 | CU3: Funds Mobilized for the month of December 2025 (INR in crore) | CV3: Repurchase/Redemption for the month of December 2025 (INR in crore) | CW3: Net Inflow (+ve)/Outflow (-ve) for the month of December 2025 (INR in crore) | CX3: Net Assets Under Management as on December 31, 2025 (INR in crore) | CY3: Average Net Assets Under Management for the month December 2025 (INR in crore) | CZ3: No. of segregated portfolios created as on December 31, 2025 | DA3: Net Assets Under Management in segregated portfolio as on December 31, 2025 (INR in crore) | DB3: - | DC3: No. of Schemes as on January 31, 2026 | DD3: No. of Folios as on January 31, 2026 | DE3: Funds Mobilized for the month of January 2026 (INR in crore) | DF3: Repurchase/Redemption for the month of January 2026 (INR in crore) | DG3: Net Inflow (+ve)/Outflow (-ve) for the month of January 2026 (INR in crore) | DH3: Net Assets Under Management as on January 31, 2026 (INR in crore) | DI3: Average Net Assets Under Management for the month January 2026 (INR in crore) | DJ3: No. of segregated portfolios created as on January 31, 2026 | DK3: Net Assets Under Management in segregated portfolio as on January 31, 2026 (INR in crore) | DL3: - | DM3: Funds Mobilized (INR in crore) | DN3: Net Inflow (+ve)/Outflow (-ve) (INR in crore) | DO3: - | DP3: GS - Growth-(Dec'25 Vs Jan'26) | DQ3: NS - Growth-(Dec'25 Vs Jan'26) | DR3: AUM - Growth-(Dec'25 Vs Jan'26) | DS3: No. of Schemes as on February 28, 2026 | DT3: No. of Folios as on February 28, 2026 | DU3: Funds Mobilized for the month of February 2026 (INR in crore) | DV3: Repurchase/Redemption for the month of February 2026 (INR in crore) | DW3: Net Inflow (+ve)/Outflow (-ve) for the month of February 2026 (INR in crore) | DX3: Net Assets Under Management as on February 28, 2026 (INR in crore) | DY3: Average Net Assets Under Management for the month February 2026 (INR in crore) | DZ3: No. of segregated portfolios created as on February 28, 2026 | EA3: Net Assets Under Management in segregated portfolio as on February 28, 2026 (INR in crore) | EB3: - | EC3: Funds Mobilized for the month of January 2026 (INR in crore) | ED3: Net Inflow (+ve)/Outflow (-ve) for the month of January 2026 (INR in crore) | EE3: - | EF3: GS - Growth-(Jan'26 Vs Feb'26) | EG3: NS - Growth-(Jan'26 Vs Feb'26) | EH3: AUM - Growth-(Jan'26 Vs Feb'26) | EI3: - | EJ3: No. of Schemes as on March 31, 2026 | EK3: No. of Folios as on March 31, 2026 | EL3: Funds Mobilized for the month of March 2026 (INR in crore) | EM3: Repurchase/Redemption for the month of March 2026 (INR in crore) | EN3: Net Inflow (+ve)/Outflow (-ve) for the month of March 2026 (INR in crore) | EO3: Net Assets Under Management as on March 31, 2026 (INR in crore) | EP3: Average Net Assets Under Management for the month March 2026 (INR in crore) | EQ3: No. of segregated portfolios created as on March 31, 2026 | ER3: Net Assets Under Management in segregated portfolio as on March 31, 2026 (INR in crore) | ES3: - | ET3: Funds Mobilized for the month of March 2026 (INR in crore) | EU3: Net Inflow (+ve)/Outflow (-ve) for the month of March 2026 (INR in crore) | EV3: - | EW3: GS - Growth-(Feb'26 Vs Mar'26) | EX3: NS - Growth-(Feb'26 Vs Mar'26) | EY3: AUM - Growth-(Feb'26 Vs Mar'26)
A4: Active Equity (incl Hybrid)
A5: Multi Asset Allocation Fund | B5: Hybrid Schemes | C5: Open ended Schemes | D5: Equity | E5: Equity-Hybrid Schemes | F5: Active Equity (incl Hybrid) | K5: =IF(OR(I5="",J5=""),"",I5-J5) | L5: 107094.5 | M5: 113587.79 | P5: - | Q5: 28 | R5: 3121223 | S5: 3583.9126 | T5: 1478.1664 | U5: 2105.7462 | V5: 113009.41 | W5: 118248.56 | X5: 0 | Y5: 0 | Z5: - | AA5: 29 | AB5: 3226116 | AC5: 4508.2554 | AD5: 1581.4557 | AE5: 2926.7997 | AF5: 118153.73 | AG5: 123714.44 | AH5: 0 | AI5: 0 | AJ5: - | AK5: 29 | AL5: 3307121 | AM5: 4514.2515 | AN5: 1304.2772 | AO5: 3209.9742 | AP5: 123584.5 | AQ5: 130104.79 | AR5: 0 | AS5: 0 | AT5: - | AU5: 29 | AV5: 3459194 | AW5: 7480.7755 | AX5: 1283.5572 | AY5: 6197.2183 | AZ5: 128426.74 | BA5: 135201 | BB5: 0 | BC5: 0 | BD5: - | BE5: 30 | BF5: 3560534 | BG5: 4633.0019 | BH5: 1105.0929 | BI5: 3527.909 | BJ5: 132103.62 | BK5: 139994.94 | BL5: 0 | BM5: 0 | BN5: - | BO5: 31 | BP5: 3704172 | BQ5: 6608.0378 | BR5: 1625.8258 | BS5: 4982.212 | BT5: 140416.72 | BU5: 147700.94 | BV5: 0 | BW5: 0 | BX5: - | BY5: 31 | BZ5: 3861455 | CA5: 6706.8455 | CB5: 1362.66 | CC5: 5344.1855 | CD5: 151071.71 | CE5: 157277.39 | CF5: 0 | CG5: 0 | CH5: - | CI5: 32 | CJ5: 4016236 | CK5: 6655.4878 | CL5: 1340.6296 | CM5: 5314.8582 | CN5: 157266.67 | CO5: 164438.98 | CP5: 0 | CQ5: 0 | CR5: - | CS5: 33 | CT5: 4249832 | CU5: 8927.2308 | CV5: 1501.2522 | CW5: 7425.9787 | CX5: 164730.83 | CY5: 173823.59 | CZ5: 0 | DA5: 0 | DB5: - | DC5: 33 | DD5: 4592478 | DE5: 12139.134 | DF5: 1653.7527 | DG5: 10485.381 | DH5: 174660.32 | DI5: 185088.95 | DJ5: 0 | DK5: 0 | DL5: - | DM5: =S5+AC5+AM5+AW5+BG5+BQ5+CA5+CK5+CU5+DE5 | DN5: =U5+AE5+AO5+AY5+BI5+BS5+CC5+CM5+CW5+DG5 | DO5: - | DP5: =IFERROR((DE5-CU5)/CU5,"-") | DQ5: =IFERROR((DG5-CW5)/CW5,"-") | DR5: =IFERROR((DH5-CX5)/CX5,"-") | DS5: 33 | DT5: 4908663 | DU5: 10151.087 | DV5: 1674.8311 | DW5: 8476.2558 | DX5: 183245.91 | DY5: 196730.61 | DZ5: 0 | EA5: 0 | EB5: - | EC5: =S5+AC5+AM5+AW5+BG5+BQ5+CA5+CK5+CU5+DE5+DU5 | ED5: =U5+AE5+AO5+AY5+BI5+BS5+CC5+CM5+CW5+DG5+DW5 | EE5: - | EF5: =IFERROR((DU5-DE5)/DE5,"-") | EG5: =IFERROR((DW5-DG5)/DG5,"-") | EH5: =IFERROR((DX5-DH5)/DH5,"-") | EI5: - | EJ5: 34 | EK5: 5160754 | EL5: 8270.4619 | EM5: 3057.7299 | EN5: 5212.732 | EO5: 173762.06 | EP5: 195113.53 | EQ5: 0 | ER5: 0 | ES5: - | ET5: =S5+AC5+AM5+AW5+BG5+BQ5+CA5+CK5+CU5+DE5+DU5+EL5 | EU5: =U5+AE5+AO5+AY5+BI5+BS5+CC5+CM5+CW5+DG5+DW5+EN5 | EV5: - | EW5: =IFERROR((EL5-DU5)/DU5,"-") | EX5: =IFERROR((EN5-DW5)/DW5,"-") | EY5: =IFERROR((EO5-DX5)/DX5,"-")
A6: Flexi Cap Fund | B6: Growth/Equity Oriented Schemes | C6: Open ended Schemes | D6: Equity | E6: Equity | F6: Active Equity (incl Hybrid) | K6: =IF(OR(I6="",J6=""),"",I6-J6) | L6: 435508.97 | M6: 422113.98 | P6: - | Q6: 39 | R6: 18209314 | S6: 10026.303 | T6: 4484.5884 | U6: 5541.7141 | V6: 454667.91 | W6: 440289.91 | X6: 0 | Y6: 0 | Z6: - | AA6: 39 | AB6: 18510887 | AC6: 9241.5932 | AD6: 5400.2711 | AE6: 3841.3221 | AF6: 471974.48 | AG6: 464765.76 | AH6: 0 | AI6: 0 | AJ6: - | AK6: 40 | AL6: 18938944 | AM6: 9525.6885 | AN6: 3792.5289 | AO6: 5733.1596 | AP6: 494278.83 | AQ6: 482665.23 | AR6: 0 | AS6: 0 | AT6: - | AU6: 40 | AV6: 19448661 | AW6: 11378.229 | AX6: 3723.9019 | AY6: 7654.3271 | AZ6: 493229.47 | BA6: 494656.52 | BB6: 0 | BC6: 0 | BD6: - | BE6: 41 | BF6: 19838017 | BG6: 11664.641 | BH6: 3985.2393 | BI6: 7679.4018 | BJ6: 495445.68 | BK6: 497155.76 | BL6: 0 | BM6: 0 | BN6: - | BO6: 41 | BP6: 20206005 | BQ6: 11354.999 | BR6: 4325.7373 | BS6: 7029.2622 | BT6: 507916.03 | BU6: 512367.92 | BV6: 0 | BW6: 0 | BX6: - | BY6: 43 | BZ6: 21182395 | CA6: 12968.501 | CB6: 4039.7958 | CC6: 8928.705 | CD6: 533756.17 | CE6: 527143.34 | CF6: 0 | CG6: 0 | CH6: - | CI6: 43 | CJ6: 21635346 | CK6: 11822.383 | CL6: 3687.3705 | CM6: 8135.0125 | CN6: 545189.58 | CO6: 539124.74 | CP6: 0 | CQ6: 0 | CR6: - | CS6: 44 | CT6: 22050009 | CU6: 14910.65 | CV6: 4891.3811 | CW6: 10019.269 | CX6: 551962.17 | CY6: 546559.61 | CZ6: 0 | DA6: 0 | DB6: - | DC6: 44 | DD6: 22515391 | DE6: 12827.395 | DF6: 5155.0348 | DG6: 7672.36 | DH6: 546946.61 | DI6: 549566.71 | DJ6: 0 | DK6: 0 | DL6: - | DM6: =S6+AC6+AM6+AW6+BG6+BQ6+CA6+CK6+CU6+DE6 | DN6: =U6+AE6+AO6+AY6+BI6+BS6+CC6+CM6+CW6+DG6 | DO6: - | DP6: =IFERROR((DE6-CU6)/CU6,"-") | DQ6: =IFERROR((DG6-CW6)/CW6,"-") | DR6: =IFERROR((DH6-CX6)/CX6,"-") | DS6: 44 | DT6: 22945488 | DU6: 11044.84 | DV6: 4120.1855 | DW6: 6924.6543 | DX6: 553187.14 | DY6: 557484.96 | DZ6: 0 | EA6: 0 | EB6: - | EC6: =S6+AC6+AM6+AW6+BG6+BQ6+CA6+CK6+CU6+DE6+DU6 | ED6: =U6+AE6+AO6+AY6+BI6+BS6+CC6+CM6+CW6+DG6+DW6 | EE6: - | EF6: =IFERROR((DU6-DE6)/DE6,"-") | EG6: =IFERROR((DW6-DG6)/DG6,"-") | EH6: =IFERROR((DX6-DH6)/DH6,"-") | EI6: - | EJ6: 45 | EK6: 23379152 | EL6: 16147.687 | EM6: 6093.5668 | EN6: 10054.12 | EO6: 505265.45 | EP6: 528059.76 | EQ6: 0 | ER6: 0 | ES6: - | ET6: =S6+AC6+AM6+AW6+BG6+BQ6+CA6+CK6+CU6+DE6+DU6+EL6 | EU6: =U6+AE6+AO6+AY6+BI6+BS6+CC6+CM6+CW6+DG6+DW6+EN6 | EV6: - | EW6: =IFERROR((EL6-DU6)/DU6,"-") | EX6: =IFERROR((EN6-DW6)/DW6,"-") | EY6: =IFERROR((EO6-DX6)/DX6,"-")
A7: Mid Cap Fund | B7: Growth/Equity Oriented Schemes | C7: Open ended Schemes | D7: Equity | E7: Equity | F7: Active Equity (incl Hybrid) | K7: =IF(OR(I7="",J7=""),"",I7-J7) | L7: 368992.08 | M7: 356671.84 | P7: - | Q7: 30 | R7: 21310959 | S7: 6748.9694 | T7: 3434.9939 | U7: 3313.9755 | V7: 383083.71 | W7: 370097.35 | X7: 0 | Y7: 0 | Z7: - | AA7: 30 | AB7: 21538476 | AC7: 6812.2399 | AD7: 4003.5601 | AE7: 2808.6797 | AF7: 408092.68 | AG7: 395846.07 | AH7: 0 | AI7: 0 | AJ7: - | AK7: 30 | AL7: 22005565 | AM7: 7539.5287 | AN7: 3785.1093 | AO7: 3754.4193 | AP7: 431699.79 | AQ7: 419404.14 | AR7: 0 | AS7: 0 | AT7: - | AU7: 30 | AV7: 22564162 | AW7: 8711.4567 | AX7: 3528.9665 | AY7: 5182.4902 | AZ7: 428582.5 | BA7: 431587.59 | BB7: 0 | BC7: 0 | BD7: - | BE7: 31 | BF7: 23000768 | BG7: 8288.3147 | BH7: 2957.6902 | BI7: 5330.6245 | BJ7: 426623.48 | BK7: 428719.14 | BL7: 0 | BM7: 0 | BN7: - | BO7: 31 | BP7: 23343247 | BQ7: 8793.4982 | BR7: 3708.1023 | BS7: 5085.3958 | BT7: 433540.25 | BU7: 439969.24 | BV7: 0 | BW7: 0 | BX7: - | BY7: 31 | BZ7: 23535313 | CA7: 8169.0274 | CB7: 4361.9156 | CC7: 3807.1118 | CD7: 454606.49 | CE7: 449162.62 | CF7: 0 | CG7: 0 | CH7: - | CI7: 31 | CJ7: 23815587 | CK7: 8226.1357 | CL7: 3739.2221 | CM7: 4486.9136 | CN7: 461830.87 | CO7: 458447.93 | CP7: 0 | CQ7: 0 | CR7: - | CS7: 31 | CT7: 23987318 | CU7: 9004.0089 | CV7: 4828.2008 | CW7: 4175.808 | CX7: 461271.23 | CY7: 458515.52 | CZ7: 0 | DA7: 0 | DB7: - | DC7: 31 | DD7: 24168250 | DE7: 8259.5798 | DF7: 5074.1054 | DG7: 3185.4744 | DH7: 449438.76 | DI7: 454270.77 | DJ7: 0 | DK7: 0 | DL7: - | DM7: =S7+AC7+AM7+AW7+BG7+BQ7+CA7+CK7+CU7+DE7 | DN7: =U7+AE7+AO7+AY7+BI7+BS7+CC7+CM7+CW7+DG7 | DO7: - | DP7: =IFERROR((DE7-CU7)/CU7,"-") | DQ7: =IFERROR((DG7-CW7)/CW7,"-") | DR7: =IFERROR((DH7-CX7)/CX7,"-") | DS7: 32 | DT7: 24460976 | DU7: 7854.608 | DV7: 3851.6136 | DW7: 4002.9945 | DX7: 462097.67 | DY7: 462469.54 | DZ7: 0 | EA7: 0 | EB7: - | EC7: =S7+AC7+AM7+AW7+BG7+BQ7+CA7+CK7+CU7+DE7+DU7 | ED7: =U7+AE7+AO7+AY7+BI7+BS7+CC7+CM7+CW7+DG7+DW7 | EE7: - | EF7: =IFERROR((DU7-DE7)/DE7,"-") | EG7: =IFERROR((DW7-DG7)/DG7,"-") | EH7: =IFERROR((DX7-DH7)/DH7,"-") | EI7: - | EJ7: 33 | EK7: 24763770 | EL7: 10769.932 | EM7: 4706.4036 | EN7: 6063.5287 | EO7: 418329.2 | EP7: 437782.59 | EQ7: 0 | ER7: 0 | ES7: - | ET7: =S7+AC7+AM7+AW7+BG7+BQ7+CA7+CK7+CU7+DE7+DU7+EL7 | EU7: =U7+AE7+AO7+AY7+BI7+BS7+CC7+CM7+CW7+DG7+DW7+EN7 | EV7: - | EW7: =IFERROR((EL7-DU7)/DU7,"-") | EX7: =IFERROR((EN7-DW7)/DW7,"-") | EY7: =IFERROR((EO7-DX7)/DX7,"-")
A8: Small Cap Fund | B8: Growth/Equity Oriented Schemes | C8: Open ended Schemes | D8: Equity | E8: Equity | F8: Active Equity (incl Hybrid) | K8: =IF(OR(I8="",J8=""),"",I8-J8) | L8: 295478.84 | M8: 288473.49 | P8: - | Q8: 30 | R8: 25141474 | S8: 7017.9 | T8: 3017.9473 | U8: 3999.9527 | V8: 307168.11 | W8: 302451.86 | X8: 0 | Y8: 0 | Z8: - | AA8: 30 | AB8: 25248991 | AC8: 6754.2126 | AD8: 3540.007 | AE8: 3214.2056 | AF8: 336005.21 | AG8: 321670.43 | AH8: 0 | AI8: 0 | AJ8: - | AK8: 30 | AL8: 25614974 | AM8: 7426.6331 | AN8: 3402.1355 | AO8: 4024.4976 | AP8: 354550.63 | AQ8: 344307.6 | AR8: 0 | AS8: 0 | AT8: - | AU8: 31 | AV8: 26255276 | AW8: 9776.2416 | AX8: 3291.8128 | AY8: 6484.4288 | AZ8: 355901.84 | BA8: 358771.3 | BB8: 0 | BC8: 0 | BD8: - | BE8: 31 | BF8: 26635485 | BG8: 7619.2617 | BH8: 2626.3521 | BI8: 4992.9096 | BJ8: 350555.21 | BK8: 352644.66 | BL8: 0 | BM8: 0 | BN8: - | BO8: 31 | BP8: 26894961 | BQ8: 8065.5209 | BR8: 3702.6071 | BS8: 4362.9138 | BT8: 356740.75 | BU8: 362741.69 | BV8: 0 | BW8: 0 | BX8: - | BY8: 31 | BZ8: 27017320 | CA8: 7660.9878 | CB8: 4184.9447 | CC8: 3476.0432 | CD8: 372362.31 | CE8: 366798.06 | CF8: 0 | CG8: 0 | CH8: - | CI8: 32 | CJ8: 27263667 | CK8: 8106.9204 | CL8: 3700.0194 | CM8: 4406.901 | CN8: 369881.92 | CO8: 370912.89 | CP8: 0 | CQ8: 0 | CR8: - | CS8: 33 | CT8: 27335457 | CU8: 8396.079 | CV8: 4572.2552 | CW8: 3823.8238 | CX8: 369003.09 | CY8: 366387.32 | CZ8: 0 | DA8: 0 | DB8: - | DC8: 34 | DD8: 27471864 | DE8: 8133.4169 | DF8: 5191.3055 | DG8: 2942.1115 | DH8: 354789.97 | DI8: 359055.59 | DJ8: 0 | DK8: 0 | DL8: - | DM8: =S8+AC8+AM8+AW8+BG8+BQ8+CA8+CK8+CU8+DE8 | DN8: =U8+AE8+AO8+AY8+BI8+BS8+CC8+CM8+CW8+DG8 | DO8: - | DP8: =IFERROR((DE8-CU8)/CU8,"-") | DQ8: =IFERROR((DG8-CW8)/CW8,"-") | DR8: =IFERROR((DH8-CX8)/CX8,"-") | DS8: 34 | DT8: 27721310 | DU8: 7591.522 | DV8: 3710.4642 | DW8: 3881.0577 | DX8: 363536.98 | DY8: 364961.07 | DZ8: 0 | EA8: 0 | EB8: - | EC8: =S8+AC8+AM8+AW8+BG8+BQ8+CA8+CK8+CU8+DE8+DU8 | ED8: =U8+AE8+AO8+AY8+BI8+BS8+CC8+CM8+CW8+DG8+DW8 | EE8: - | EF8: =IFERROR((DU8-DE8)/DE8,"-") | EG8: =IFERROR((DW8-DG8)/DG8,"-") | EH8: =IFERROR((DX8-DH8)/DH8,"-") | EI8: - | EJ8: 36 | EK8: 27995339 | EL8: 10674.845 | EM8: 4411.2848 | EN8: 6263.5603 | EO8: 334662.34 | EP8: 347116.55 | EQ8: 0 | ER8: 0 | ES8: - | ET8: =S8+AC8+AM8+AW8+BG8+BQ8+CA8+CK8+CU8+DE8+DU8+EL8 | EU8: =U8+AE8+AO8+AY8+BI8+BS8+CC8+CM8+CW8+DG8+DW8+EN8 | EV8: - | EW8: =IFERROR((EL8-DU8)/DU8,"-") | EX8: =IFERROR((EN8-DW8)/DW8,"-") | EY8: =IFERROR((EO8-DX8)/DX8,"-")
A9: Large & Mid Cap Fund | B9: Growth/Equity Oriented Schemes | C9: Open ended Schemes | D9: Equity | E9: Equity | F9: Active Equity (incl Hybrid) | K9: =IF(OR(I9="",J9=""),"",I9-J9) | L9: 263206.56 | M9: 254637.15 | P9: - | Q9: 31 | R9: 11957644 | S9: 5485.4328 | T9: 2933.3766 | U9: 2552.0562 | V9: 273258.42 | W9: 265202.48 | X9: 0 | Y9: 0 | Z9: - | AA9: 31 | AB9: 12069826 | AC9: 5352.7175 | AD9: 2662.0301 | AE9: 2690.6874 | AF9: 287392.5 | AG9: 280686.22 | AH9: 0 | AI9: 0 | AJ9: - | AK9: 32 | AL9: 12262237 | AM9: 5847.9355 | AN9: 2351.0242 | AO9: 3496.9113 | AP9: 302139.03 | AQ9: 294474.58 | AR9: 0 | AS9: 0 | AT9: - | AU9: 33 | AV9: 12511660 | AW9: 7399.657 | AX9: 2364.9434 | AY9: 5034.7136 | AZ9: 300972.11 | BA9: 302807.78 | BB9: 0 | BC9: 0 | BD9: - | BE9: 33 | BF9: 12691674 | BG9: 5501.9524 | BH9: 2176.295 | BI9: 3325.6574 | BJ9: 299335.05 | BK9: 301161.33 | BL9: 0 | BM9: 0 | BN9: - | BO9: 33 | BP9: 12853471 | BQ9: 6769.3997 | BR9: 2964.2346 | BS9: 3805.1651 | BT9: 306903.35 | BU9: 309862.4 | BV9: 0 | BW9: 0 | BX9: - | BY9: 33 | BZ9: 12989734 | CA9: 6037.2192 | CB9: 2860.1506 | CC9: 3177.0685 | CD9: 322158.21 | CE9: 317917.72 | CF9: 0 | CG9: 0 | CH9: - | CI9: 33 | CJ9: 13165462 | CK9: 6979.0164 | CL9: 2475.7016 | CM9: 4503.3148 | CN9: 329325.16 | CO9: 325878.91 | CP9: 0 | CQ9: 0 | CR9: - | CS9: 33 | CT9: 13297987 | CU9: 7079.1563 | CV9: 2985.6504 | CW9: 4093.5059 | CX9: 331287.38 | CY9: 328384.34 | CZ9: 0 | DA9: 0 | DB9: - | DC9: 33 | DD9: 13434952 | DE9: 6423.9105 | DF9: 3242.0196 | DG9: 3181.8909 | DH9: 324621.33 | DI9: 327288.02 | DJ9: 0 | DK9: 0 | DL9: - | DM9: =S9+AC9+AM9+AW9+BG9+BQ9+CA9+CK9+CU9+DE9 | DN9: =U9+AE9+AO9+AY9+BI9+BS9+CC9+CM9+CW9+DG9 | DO9: - | DP9: =IFERROR((DE9-CU9)/CU9,"-") | DQ9: =IFERROR((DG9-CW9)/CW9,"-") | DR9: =IFERROR((DH9-CX9)/CX9,"-") | DS9: 33 | DT9: 13582421 | DU9: 5841.7482 | DV9: 2704.0179 | DW9: 3137.7303 | DX9: 331893.1 | DY9: 332993.59 | DZ9: 0 | EA9: 0 | EB9: - | EC9: =S9+AC9+AM9+AW9+BG9+BQ9+CA9+CK9+CU9+DE9+DU9 | ED9: =U9+AE9+AO9+AY9+BI9+BS9+CC9+CM9+CW9+DG9+DW9 | EE9: - | EF9: =IFERROR((DU9-DE9)/DE9,"-") | EG9: =IFERROR((DW9-DG9)/DG9,"-") | EH9: =IFERROR((DX9-DH9)/DH9,"-") | EI9: - | EJ9: 33 | EK9: 13722688 | EL9: 9007.3707 | EM9: 3700.1235 | EN9: 5307.2472 | EO9: 299467.98 | EP9: 314204.09 | EQ9: 0 | ER9: 0 | ES9: - | ET9: =S9+AC9+AM9+AW9+BG9+BQ9+CA9+CK9+CU9+DE9+DU9+EL9 | EU9: =U9+AE9+AO9+AY9+BI9+BS9+CC9+CM9+CW9+DG9+DW9+EN9 | EV9: - | EW9: =IFERROR((EL9-DU9)/DU9,"-") | EX9: =IFERROR((EN9-DW9)/DW9,"-") | EY9: =IFERROR((EO9-DX9)/DX9,"-")
A10: Sectoral/Thematic Funds | B10: Growth/Equity Oriented Schemes | C10: Open ended Schemes | D10: Equity | E10: Equity | F10: Active Equity (incl Hybrid) | K10: =IF(OR(I10="",J10=""),"",I10-J10) | L10: 455088.24 | M10: 443499.84 | P10: - | Q10: 213 | R10: 30895904 | S10: 10060.067 | T10: 8059.1216 | U10: 2000.9458 | V10: 470339.04 | W10: 457166.12 | X10: 0 | Y10: 0 | Z10: - | AA10: 215 | AB10: 30982541 | AC10: 10621.097 | AD10: 8568.6122 | AE10: 2052.4844 | AF10: 492403.81 | AG10: 481284.64 | AH10: 0 | AI10: 0 | AJ10: - | AK10: 217 | AL10: 31140356 | AM10: 9633.7916 | AN10: 9158.1857 | AO10: 475.60585 | AP10: 509344.83 | AQ10: 499575.1 | AR10: 0 | AS10: 0 | AT10: - | AU10: 224 | AV10: 31771659 | AW10: 18092.629 | AX10: 8666.6032 | AY10: 9426.0262 | AZ10: 509519.21 | BA10: 509953.74 | BB10: 0 | BC10: 0 | BD10: - | BE10: 226 | BF10: 31939915 | BG10: 10929.155 | BH10: 7035.9918 | BI10: 3893.1634 | BJ10: 506571.7 | BK10: 508546.18 | BL10: 0 | BM10: 0 | BN10: - | BO10: 227 | BP10: 31889078 | BQ10: 11167.475 | BR10: 9946.5845 | BS10: 1220.891 | BT10: 513469.44 | BU10: 520090.15 | BV10: 0 | BW10: 0 | BX10: - | BY10: 231 | BZ10: 31811396 | CA10: 11776.953 | CB10: 10410.792 | CC10: 1366.1616 | CD10: 533830.68 | CE10: 527588.94 | CF10: 0 | CG10: 0 | CH10: - | CI10: 235 | CJ10: 31879923 | CK10: 10959.588 | CL10: 9094.6008 | CM10: 1864.9877 | CN10: 538180.29 | CO10: 534941.46 | CP10: 0 | CQ10: 0 | CR10: - | CS10: 238 | CT10: 31747483 | CU10: 11033.943 | CV10: 10087.956 | CW10: 945.98756 | CX10: 537666.6 | CY10: 535256.97 | CZ10: 0 | DA10: 0 | DB10: - | DC10: 240 | DD10: 31681759 | DE10: 11116.922 | DF10: 10074.358 | DG10: 1042.5646 | DH10: 523743.15 | DI10: 529376.94 | DJ10: 0 | DK10: 0 | DL10: - | DM10: =S10+AC10+AM10+AW10+BG10+BQ10+CA10+CK10+CU10+DE10 | DN10: =U10+AE10+AO10+AY10+BI10+BS10+CC10+CM10+CW10+DG10 | DO10: - | DP10: =IFERROR((DE10-CU10)/CU10,"-") | DQ10: =IFERROR((DG10-CW10)/CW10,"-") | DR10: =IFERROR((DH10-CX10)/CX10,"-") | DS10: 246 | DT10: 31953492 | DU10: 13094.129 | DV10: 10106.843 | DW10: 2987.2857 | DX10: 529804.2 | DY10: 531410.45 | DZ10: 0 | EA10: 0 | EB10: - | EC10: =S10+AC10+AM10+AW10+BG10+BQ10+CA10+CK10+CU10+DE10+DU10 | ED10: =U10+AE10+AO10+AY10+BI10+BS10+CC10+CM10+CW10+DG10+DW10 | EE10: - | EF10: =IFERROR((DU10-DE10)/DE10,"-") | EG10: =IFERROR((DW10-DG10)/DG10,"-") | EH10: =IFERROR((DX10-DH10)/DH10,"-") | EI10: - | EJ10: 250 | EK10: 32127595 | EL10: 13554.205 | EM10: 10855.382 | EN10: 2698.8231 | EO10: 477309.05 | EP10: 500854.01 | EQ10: 0 | ER10: 0 | ES10: - | ET10: =S10+AC10+AM10+AW10+BG10+BQ10+CA10+CK10+CU10+DE10+DU10+EL10 | EU10: =U10+AE10+AO10+AY10+BI10+BS10+CC10+CM10+CW10+DG10+DW10+EN10 | EV10: - | EW10: =IFERROR((EL10-DU10)/DU10,"-") | EX10: =IFERROR((EN10-DW10)/DW10,"-") | EY10: =IFERROR((EO10-DX10)/DX10,"-")
A11: Large Cap Fund | B11: Growth/Equity Oriented Schemes | C11: Open ended Schemes | D11: Equity | E11: Equity | F11: Active Equity (incl Hybrid) | K11: =IF(OR(I11="",J11=""),"",I11-J11) | L11: 359775.39 | M11: 348889.45 | P11: - | Q11: 33 | R11: 16090916 | S11: 5891.4498 | T11: 3219.9861 | U11: 2671.4636 | V11: 374519.71 | W11: 361853.46 | X11: 0 | Y11: 0 | Z11: - | AA11: 33 | AB11: 16175181 | AC11: 5240.699 | AD11: 3990.2248 | AE11: 1250.4742 | AF11: 383666.59 | AG11: 380250.63 | AH11: 0 | AI11: 0 | AJ11: - | AK11: 33 | AL11: 16304538 | AM11: 5171.3407 | AN11: 3477.0089 | AO11: 1694.3318 | AP11: 397470.47 | AQ11: 389566.41 | AR11: 0 | AS11: 0 | AT11: - | AU11: 33 | AV11: 16444374 | AW11: 5503.6666 | AX11: 3378.5763 | AY11: 2125.0903 | AZ11: 391762.73 | BA11: 394905.27 | BB11: 0 | BC11: 0 | BD11: - | BE11: 33 | BF11: 16539476 | BG11: 5475.3981 | BH11: 2640.5166 | BI11: 2834.8815 | BJ11: 389982.59 | BK11: 392379.06 | BL11: 0 | BM11: 0 | BN11: - | BO11: 33 | BP11: 16625122 | BQ11: 5576.8187 | BR11: 3257.7771 | BS11: 2319.0416 | BT11: 395093.32 | BU11: 399779.69 | BV11: 0 | BW11: 0 | BX11: - | BY11: 33 | BZ11: 16696893 | CA11: 5293.268 | CB11: 4321.296 | CC11: 971.97199 | CD11: 410156.51 | CE11: 407307.68 | CF11: 0 | CG11: 0 | CH11: - | CI11: 33 | CJ11: 16796845 | CK11: 4942.3569 | CL11: 3302.5523 | CM11: 1639.8047 | CN11: 418524.98 | CO11: 413988.88 | CP11: 0 | CQ11: 0 | CR11: - | CS11: 33 | CT11: 16870064 | CU11: 5499.6024 | CV11: 3932.1796 | CW11: 1567.4228 | CX11: 418726.65 | CY11: 417491.58 | CZ11: 0 | DA11: 0 | DB11: - | DC11: 33 | DD11: 16949451 | DE11: 5523.629 | DF11: 3518.6518 | DG11: 2004.9772 | DH11: 408303.5 | DI11: 413609.67 | DJ11: 0 | DK11: 0 | DL11: - | DM11: =S11+AC11+AM11+AW11+BG11+BQ11+CA11+CK11+CU11+DE11 | DN11: =U11+AE11+AO11+AY11+BI11+BS11+CC11+CM11+CW11+DG11 | DO11: - | DP11: =IFERROR((DE11-CU11)/CU11,"-") | DQ11: =IFERROR((DG11-CW11)/CW11,"-") | DR11: =IFERROR((DH11-CX11)/CX11,"-") | DS11: 34 | DT11: 17074655 | DU11: 5537.8692 | DV11: 3426.1937 | DW11: 2111.6755 | DX11: 411231.74 | DY11: 415950.82 | DZ11: 0 | EA11: 0 | EB11: - | EC11: =S11+AC11+AM11+AW11+BG11+BQ11+CA11+CK11+CU11+DE11+DU11 | ED11: =U11+AE11+AO11+AY11+BI11+BS11+CC11+CM11+CW11+DG11+DW11 | EE11: - | EF11: =IFERROR((DU11-DE11)/DE11,"-") | EG11: =IFERROR((DW11-DG11)/DG11,"-") | EH11: =IFERROR((DX11-DH11)/DH11,"-") | EI11: - | EJ11: 34 | EK11: 17144363 | EL11: 7209.1027 | EM11: 4211.263 | EN11: 2997.8397 | EO11: 366045.49 | EP11: 387415.68 | EQ11: 0 | ER11: 0 | ES11: - | ET11: =S11+AC11+AM11+AW11+BG11+BQ11+CA11+CK11+CU11+DE11+DU11+EL11 | EU11: =U11+AE11+AO11+AY11+BI11+BS11+CC11+CM11+CW11+DG11+DW11+EN11 | EV11: - | EW11: =IFERROR((EL11-DU11)/DU11,"-") | EX11: =IFERROR((EN11-DW11)/DW11,"-") | EY11: =IFERROR((EO11-DX11)/DX11,"-")
A12: Multi Cap Fund | B12: Growth/Equity Oriented Schemes | C12: Open ended Schemes | D12: Equity | E12: Equity | F12: Active Equity (incl Hybrid) | K12: =IF(OR(I12="",J12=""),"",I12-J12) | L12: 175724.35 | M12: 169398.9 | P12: - | Q12: 30 | R12: 9635087 | S12: 4377.9626 | T12: 1826.2546 | U12: 2551.708 | V12: 183132.81 | W12: 177702.64 | X12: 0 | Y12: 0 | Z12: - | AA12: 31 | AB12: 9826483 | AC12: 5240.159 | AD12: 2240.8731 | AE12: 2999.2859 | AF12: 195159.76 | AG12: 188891.17 | AH12: 0 | AI12: 0 | AJ12: - | AK12: 31 | AL12: 10058599 | AM12: 4717.8981 | AN12: 1923.6963 | AO12: 2794.2018 | AP12: 204689.94 | AQ12: 199461.04 | AR12: 0 | AS12: 0 | AT12: - | AU12: 32 | AV12: 10357646 | AW12: 5961.1287 | AX12: 1970.29 | AY12: 3990.8387 | AZ12: 205281.89 | BA12: 205917.39 | BB12: 0 | BC12: 0 | BD12: - | BE12: 32 | BF12: 10582438 | BG12: 4812.7817 | BH12: 1619.7267 | BI12: 3193.055 | BJ12: 205141.48 | BK12: 205535.81 | BL12: 0 | BM12: 0 | BN12: - | BO12: 32 | BP12: 10786468 | BQ12: 5783.8014 | BR12: 2224.2357 | BS12: 3559.5657 | BT12: 210368.99 | BU12: 212137.47 | BV12: 0 | BW12: 0 | BX12: - | BY12: 32 | BZ12: 10912552 | CA12: 4903.9412 | CB12: 2403.5084 | CC12: 2500.4328 | CD12: 220254.63 | CE12: 217508.32 | CF12: 0 | CG12: 0 | CH12: - | CI12: 32 | CJ12: 11066021 | CK12: 5011.8538 | CL12: 2549.0088 | CM12: 2462.845 | CN12: 222749.03 | CO12: 221497.62 | CP12: 0 | CQ12: 0 | CR12: - | CS12: 32 | CT12: 11173881 | CU12: 5163.2837 | CV12: 2908.3303 | CW12: 2254.9533 | CX12: 223101.79 | CY12: 221480.12 | CZ12: 0 | DA12: 0 | DB12: - | DC12: 32 | DD12: 11272944 | DE12: 5043.0453 | DF12: 3047.8132 | DG12: 1995.2321 | DH12: 216445.39 | DI12: 218817.58 | DJ12: 0 | DK12: 0 | DL12: - | DM12: =S12+AC12+AM12+AW12+BG12+BQ12+CA12+CK12+CU12+DE12 | DN12: =U12+AE12+AO12+AY12+BI12+BS12+CC12+CM12+CW12+DG12 | DO12: - | DP12: =IFERROR((DE12-CU12)/CU12,"-") | DQ12: =IFERROR((DG12-CW12)/CW12,"-") | DR12: =IFERROR((DH12-CX12)/CX12,"-") | DS12: 32 | DT12: 11374795 | DU12: 4387.9214 | DV12: 2454.3875 | DW12: 1933.5339 | DX12: 221586.09 | DY12: 222464.01 | DZ12: 0 | EA12: 0 | EB12: - | EC12: =S12+AC12+AM12+AW12+BG12+BQ12+CA12+CK12+CU12+DE12+DU12 | ED12: =U12+AE12+AO12+AY12+BI12+BS12+CC12+CM12+CW12+DG12+DW12 | EE12: - | EF12: =IFERROR((DU12-DE12)/DE12,"-") | EG12: =IFERROR((DW12-DG12)/DG12,"-") | EH12: =IFERROR((DX12-DH12)/DH12,"-") | EI12: - | EJ12: 32 | EK12: 11482274 | EL12: 5819.8736 | EM12: 2838.3248 | EN12: 2981.5487 | EO12: 200439.13 | EP12: 210283.52 | EQ12: 0 | ER12: 0 | ES12: - | ET12: =S12+AC12+AM12+AW12+BG12+BQ12+CA12+CK12+CU12+DE12+DU12+EL12 | EU12: =U12+AE12+AO12+AY12+BI12+BS12+CC12+CM12+CW12+DG12+DW12+EN12 | EV12: - | EW12: =IFERROR((EL12-DU12)/DU12,"-") | EX12: =IFERROR((EN12-DW12)/DW12,"-") | EY12: =IFERROR((EO12-DX12)/DX12,"-")
A13: Dynamic Asset Allocation/Balanced Advantage Fund | B13: Hybrid Schemes | C13: Open ended Schemes | D13: Equity | E13: Equity-Hybrid Schemes | F13: Active Equity (incl Hybrid) | K13: =IF(OR(I13="",J13=""),"",I13-J13) | L13: 283673.4 | M13: 279386.23 | P13: - | Q13: 35 | R13: 5252235 | S13: 4010.2015 | T13: 3128.9677 | U13: 881.23381 | V13: 292549.95 | W13: 286751.76 | X13: 0 | Y13: 0 | Z13: - | AA13: 35 | AB13: 5288342 | AC13: 4438.8758 | AD13: 3302.7596 | AE13: 1136.1162 | AF13: 299506.76 | AG13: 296512.19 | AH13: 0 | AI13: 0 | AJ13: - | AK13: 35 | AL13: 5342869 | AM13: 4913.1381 | AN13: 3027.6082 | AO13: 1885.5299 | AP13: 306648.51 | AQ13: 303164.82 | AR13: 0 | AS13: 0 | AT13: - | AU13: 35 | AV13: 5425213 | AW13: 5996.0994 | AX13: 3384.9118 | AY13: 2611.1876 | AZ13: 305086.55 | BA13: 307392.82 | BB13: 0 | BC13: 0 | BD13: - | BE13: 35 | BF13: 5474637 | BG13: 4809.9566 | BH13: 2493.472 | BI13: 2316.4846 | BJ13: 304727.5 | BK13: 306186.21 | BL13: 0 | BM13: 0 | BN13: - | BO13: 35 | BP13: 5509198 | BQ13: 5003.9812 | BR13: 3315.4256 | BS13: 1688.5556 | BT13: 309385.04 | BU13: 311226.53 | BV13: 0 | BW13: 0 | BX13: - | BY13: 35 | BZ13: 5530506 | CA13: 4233.7801 | CB13: 3694.1281 | CC13: 539.65205 | CD13: 318121.66 | CE13: 316548.77 | CF13: 0 | CG13: 0 | CH13: - | CI13: 35 | CJ13: 5565740 | CK13: 4482.1312 | CL13: 3072.127 | CM13: 1410.0042 | CN13: 322208.64 | CO13: 320995.1 | CP13: 0 | CQ13: 0 | CR13: - | CS13: 35 | CT13: 5595687 | CU13: 4660.7802 | CV13: 3563.5837 | CW13: 1097.1965 | CX13: 323324.83 | CY13: 323093.25 | CZ13: 0 | DA13: 0 | DB13: - | DC13: 35 | DD13: 5624351 | DE13: 5279.5107 | DF13: 3440.096 | DG13: 1839.4147 | DH13: 319902.64 | DI13: 322414.84 | DJ13: 0 | DK13: 0 | DL13: - | DM13: =S13+AC13+AM13+AW13+BG13+BQ13+CA13+CK13+CU13+DE13 | DN13: =U13+AE13+AO13+AY13+BI13+BS13+CC13+CM13+CW13+DG13 | DO13: - | DP13: =IFERROR((DE13-CU13)/CU13,"-") | DQ13: =IFERROR((DG13-CW13)/CW13,"-") | DR13: =IFERROR((DH13-CX13)/CX13,"-") | DS13: 36 | DT13: 5670757 | DU13: 4745.2108 | DV13: 3223.6398 | DW13: 1521.571 | DX13: 323655.44 | DY13: 325355.67 | DZ13: 0 | EA13: 0 | EB13: - | EC13: =S13+AC13+AM13+AW13+BG13+BQ13+CA13+CK13+CU13+DE13+DU13 | ED13: =U13+AE13+AO13+AY13+BI13+BS13+CC13+CM13+CW13+DG13+DW13 | EE13: - | EF13: =IFERROR((DU13-DE13)/DE13,"-") | EG13: =IFERROR((DW13-DG13)/DG13,"-") | EH13: =IFERROR((DX13-DH13)/DH13,"-") | EI13: - | EJ13: 36 | EK13: 5704774 | EL13: 4570.4626 | EM13: 4852.976 | EN13: -282.51341 | EO13: 299019.05 | EP13: 311460.77 | EQ13: 0 | ER13: 0 | ES13: - | ET13: =S13+AC13+AM13+AW13+BG13+BQ13+CA13+CK13+CU13+DE13+DU13+EL13 | EU13: =U13+AE13+AO13+AY13+BI13+BS13+CC13+CM13+CW13+DG13+DW13+EN13 | EV13: - | EW13: =IFERROR((EL13-DU13)/DU13,"-") | EX13: =IFERROR((EN13-DW13)/DW13,"-") | EY13: =IFERROR((EO13-DX13)/DX13,"-")
A14: Balanced Hybrid Fund/Aggressive Hybrid Fund | B14: Hybrid Schemes | C14: Open ended Schemes | D14: Equity | E14: Equity-Hybrid Schemes | F14: Active Equity (incl Hybrid) | K14: =IF(OR(I14="",J14=""),"",I14-J14) | L14: 219203.86 | M14: 214953.73 | P14: - | Q14: 31 | R14: 5786464 | S14: 2442.8369 | T14: 2594.3097 | U14: -151.47279 | V14: 226008.04 | W14: 221668.36 | X14: 1 | Y14: 0 | Z14: - | AA14: 31 | AB14: 5805601 | AC14: 2625.0926 | AD14: 2283.7023 | AE14: 341.39031 | AF14: 231900.98 | AG14: 229986.39 | AH14: 1 | AI14: 0 | AJ14: - | AK14: 31 | AL14: 5847771 | AM14: 3323.3975 | AN14: 1991.8972 | AO14: 1331.5003 | AP14: 238686.36 | AQ14: 236080.74 | AR14: 1 | AS14: 0 | AT14: - | AU14: 31 | AV14: 5912528 | AW14: 4305.6945 | AX14: 1942.1303 | AY14: 2363.5642 | AZ14: 237969.21 | BA14: 240277.48 | BB14: 1 | BC14: 0 | BD14: - | BE14: 31 | BF14: 5964898 | BG14: 3519.381 | BH14: 1648.9855 | BI14: 1870.3955 | BJ14: 236817.91 | BK14: 238877.01 | BL14: 1 | BM14: 0 | BN14: - | BO14: 31 | BP14: 6011535 | BQ14: 4032.0308 | BR14: 2018.2965 | BS14: 2013.7343 | BT14: 241559.83 | BU14: 243393.86 | BV14: 1 | BW14: 0 | BX14: - | BY14: 31 | BZ14: 6044444 | CA14: 3282.7882 | CB14: 2143.6117 | CC14: 1139.1765 | CD14: 250052.41 | CE14: 249009.9 | CF14: 1 | CG14: 0 | CH14: - | CI14: 31 | CJ14: 6089957 | CK14: 3551.1003 | CL14: 2165.7635 | CM14: 1385.3368 | CN14: 253121.18 | CO14: 252228.24 | CP14: 1 | CQ14: 0 | CR14: - | CS14: 31 | CT14: 6134634 | CU14: 3824.21 | CV14: 2310.3507 | CW14: 1513.8592 | CX14: 253233.73 | CY14: 253602.36 | CZ14: 1 | DA14: 0 | DB14: - | DC14: 31 | DD14: 6177349 | DE14: 3973.708 | DF14: 2295.5444 | DG14: 1678.1636 | DH14: 249182.03 | DI14: 252120.47 | DJ14: 1 | DK14: 0 | DL14: - | DM14: =S14+AC14+AM14+AW14+BG14+BQ14+CA14+CK14+CU14+DE14 | DN14: =U14+AE14+AO14+AY14+BI14+BS14+CC14+CM14+CW14+DG14 | DO14: - | DP14: =IFERROR((DE14-CU14)/CU14,"-") | DQ14: =IFERROR((DG14-CW14)/CW14,"-") | DR14: =IFERROR((DH14-CX14)/CX14,"-") | DS14: 31 | DT14: 6219899 | DU14: 3464.7082 | DV14: 2045.5003 | DW14: 1419.2079 | DX14: 252393.86 | DY14: 254563.79 | DZ14: 1 | EA14: 0 | EB14: - | EC14: =S14+AC14+AM14+AW14+BG14+BQ14+CA14+CK14+CU14+DE14+DU14 | ED14: =U14+AE14+AO14+AY14+BI14+BS14+CC14+CM14+CW14+DG14+DW14 | EE14: - | EF14: =IFERROR((DU14-DE14)/DE14,"-") | EG14: =IFERROR((DW14-DG14)/DG14,"-") | EH14: =IFERROR((DX14-DH14)/DH14,"-") | EI14: - | EJ14: 31 | EK14: 6254655 | EL14: 3527.2116 | EM14: 2532.681 | EN14: 994.53053 | EO14: 232005.53 | EP14: 242445.83 | EQ14: 1 | ER14: 0 | ES14: - | ET14: =S14+AC14+AM14+AW14+BG14+BQ14+CA14+CK14+CU14+DE14+DU14+EL14 | EU14: =U14+AE14+AO14+AY14+BI14+BS14+CC14+CM14+CW14+DG14+DW14+EN14 | EV14: - | EW14: =IFERROR((EL14-DU14)/DU14,"-") | EX14: =IFERROR((EN14-DW14)/DW14,"-") | EY14: =IFERROR((EO14-DX14)/DX14,"-")
A15: Focused Fund | B15: Growth/Equity Oriented Schemes | C15: Open ended Schemes | D15: Equity | E15: Equity | F15: Active Equity (incl Hybrid) | K15: =IF(OR(I15="",J15=""),"",I15-J15) | L15: 144791.04 | M15: 139975.78 | P15: - | Q15: 28 | R15: 5233413 | S15: 2409.0274 | T15: 1524.2699 | U15: 884.75752 | V15: 150223.05 | W15: 145808.93 | X15: 0 | Y15: 0 | Z15: - | AA15: 28 | AB15: 5246530 | AC15: 2715.7808 | AD15: 1768.6016 | AE15: 947.17915 | AF15: 155870.44 | AG15: 153127.92 | AH15: 0 | AI15: 0 | AJ15: - | AK15: 28 | AL15: 5270077 | AM15: 2338.9052 | AN15: 1373.8587 | AO15: 965.04642 | AP15: 162172.57 | AQ15: 158520.26 | AR15: 0 | AS15: 0 | AT15: - | AU15: 28 | AV15: 5298700 | AW15: 2981.6852 | AX15: 1375.7235 | AY15: 1605.9617 | AZ15: 160567.18 | BA15: 161580.85 | BB15: 0 | BC15: 0 | BD15: - | BE15: 28 | BF15: 5325168 | BG15: 2315.8985 | BH15: 1160.7197 | BI15: 1155.1788 | BJ15: 159952.07 | BK15: 160556.69 | BL15: 0 | BM15: 0 | BN15: - | BO15: 28 | BP15: 5346169 | BQ15: 2866.8032 | BR15: 1459.5757 | BS15: 1407.2275 | BT15: 162968.75 | BU15: 164734.32 | BV15: 0 | BW15: 0 | BX15: - | BY15: 28 | BZ15: 5359834 | CA15: 2538.6933 | CB15: 1599.6349 | CC15: 939.05832 | CD15: 170127.72 | CE15: 168387.2 | CF15: 0 | CG15: 0 | CH15: - | CI15: 28 | CJ15: 5386533 | CK15: 3575.7648 | CL15: 1536.0301 | CM15: 2039.7347 | CN15: 174618.42 | CO15: 172377.76 | CP15: 0 | CQ15: 0 | CR15: - | CS15: 28 | CT15: 5415223 | CU15: 2720.2336 | CV15: 1663.4089 | CW15: 1056.8247 | CX15: 174834.13 | CY15: 174196.74 | CZ15: 0 | DA15: 0 | DB15: - | DC15: 28 | DD15: 5450285 | DE15: 3280.799 | DF15: 1723.8435 | DG15: 1556.9555 | DH15: 171535.16 | DI15: 173290.06 | DJ15: 0 | DK15: 0 | DL15: - | DM15: =S15+AC15+AM15+AW15+BG15+BQ15+CA15+CK15+CU15+DE15 | DN15: =U15+AE15+AO15+AY15+BI15+BS15+CC15+CM15+CW15+DG15 | DO15: - | DP15: =IFERROR((DE15-CU15)/CU15,"-") | DQ15: =IFERROR((DG15-CW15)/CW15,"-") | DR15: =IFERROR((DH15-CX15)/CX15,"-") | DS15: 28 | DT15: 5487816 | DU15: 2467.1431 | DV15: 1566.4257 | DW15: 900.71734 | DX15: 172879.66 | DY15: 174581.19 | DZ15: 0 | EA15: 0 | EB15: - | EC15: =S15+AC15+AM15+AW15+BG15+BQ15+CA15+CK15+CU15+DE15+DU15 | ED15: =U15+AE15+AO15+AY15+BI15+BS15+CC15+CM15+CW15+DG15+DW15 | EE15: - | EF15: =IFERROR((DU15-DE15)/DE15,"-") | EG15: =IFERROR((DW15-DG15)/DG15,"-") | EH15: =IFERROR((DX15-DH15)/DH15,"-") | EI15: - | EJ15: 28 | EK15: 5514885 | EL15: 4371.4559 | EM15: 1946.8701 | EN15: 2424.5858 | EO15: 155861.22 | EP15: 163751.3 | EQ15: 0 | ER15: 0 | ES15: - | ET15: =S15+AC15+AM15+AW15+BG15+BQ15+CA15+CK15+CU15+DE15+DU15+EL15 | EU15: =U15+AE15+AO15+AY15+BI15+BS15+CC15+CM15+CW15+DG15+DW15+EN15 | EV15: - | EW15: =IFERROR((EL15-DU15)/DU15,"-") | EX15: =IFERROR((EN15-DW15)/DW15,"-") | EY15: =IFERROR((EO15-DX15)/DX15,"-")
A16: Value Fund/Contra Fund | B16: Growth/Equity Oriented Schemes | C16: Open ended Schemes | D16: Equity | E16: Equity | F16: Active Equity (incl Hybrid) | K16: =IF(OR(I16="",J16=""),"",I16-J16) | L16: 183906.07 | M16: 178490.57 | P16: - | Q16: 24 | R16: 8307959 | S16: 2713.7138 | T16: 1640.5 | U16: 1073.2138 | V16: 190856.6 | W16: 184757.15 | X16: 0 | Y16: 0 | Z16: - | AA16: 24 | AB16: 8368668 | AC16: 2812.71 | AD16: 2904.9896 | AE16: -92.279532 | AF16: 196339.39 | AG16: 193702.93 | AH16: 0 | AI16: 0 | AJ16: - | AK16: 24 | AL16: 8450603 | AM16: 2803.5817 | AN16: 1644.1425 | AO16: 1159.4391 | AP16: 203756.28 | AQ16: 199511.25 | AR16: 0 | AS16: 0 | AT16: - | AU16: 24 | AV16: 8547004 | AW16: 3135.2837 | AX16: 1665.276 | AY16: 1470.0076 | AZ16: 201203.79 | BA16: 203431.48 | BB16: 0 | BC16: 0 | BD16: - | BE16: 24 | BF16: 8612986 | BG16: 2576.5061 | BH16: 1435.4749 | BI16: 1141.0312 | BJ16: 198969.56 | BK16: 200275.63 | BL16: 0 | BM16: 0 | BN16: - | BO16: 25 | BP16: 8785142 | BQ16: 4033.7858 | BR16: 1925.8548 | BS16: 2107.931 | BT16: 204298.58 | BU16: 205770.81 | BV16: 0 | BW16: 0 | BX16: - | BY16: 25 | BZ16: 8788244 | CA16: 2590.6719 | CB16: 2222.2821 | CC16: 368.3898 | CD16: 213021.35 | CE16: 210507.57 | CF16: 0 | CG16: 0 | CH16: - | CI16: 25 | CJ16: 8830956 | CK16: 3215.108 | CL16: 1995.6639 | CM16: 1219.4441 | CN16: 217555.44 | CO16: 215017.29 | CP16: 0 | CQ16: 0 | CR16: - | CS16: 25 | CT16: 8857029 | CU16: 3444.8385 | CV16: 2356.3282 | CW16: 1088.5103 | CX16: 219127.72 | CY16: 217176.2 | CZ16: 0 | DA16: 0 | DB16: - | DC16: 25 | DD16: 8885986 | DE16: 3054.7944 | DF16: 2061.9068 | DG16: 992.88753 | DH16: 214214.78 | DI16: 215977.28 | DJ16: 0 | DK16: 0 | DL16: - | DM16: =S16+AC16+AM16+AW16+BG16+BQ16+CA16+CK16+CU16+DE16 | DN16: =U16+AE16+AO16+AY16+BI16+BS16+CC16+CM16+CW16+DG16 | DO16: - | DP16: =IFERROR((DE16-CU16)/CU16,"-") | DQ16: =IFERROR((DG16-CW16)/CW16,"-") | DR16: =IFERROR((DH16-CX16)/CX16,"-") | DS16: 25 | DT16: 8927937 | DU16: 2566.1783 | DV16: 1839.1124 | DW16: 727.06595 | DX16: 215264.76 | DY16: 216730.33 | DZ16: 0 | EA16: 0 | EB16: - | EC16: =S16+AC16+AM16+AW16+BG16+BQ16+CA16+CK16+CU16+DE16+DU16 | ED16: =U16+AE16+AO16+AY16+BI16+BS16+CC16+CM16+CW16+DG16+DW16 | EE16: - | EF16: =IFERROR((DU16-DE16)/DE16,"-") | EG16: =IFERROR((DW16-DG16)/DG16,"-") | EH16: =IFERROR((DX16-DH16)/DH16,"-") | EI16: - | EJ16: 25 | EK16: 8965112 | EL16: 4281.0469 | EM16: 2125.4932 | EN16: 2155.5537 | EO16: 193985.76 | EP16: 203829.55 | EQ16: 0 | ER16: 0 | ES16: - | ET16: =S16+AC16+AM16+AW16+BG16+BQ16+CA16+CK16+CU16+DE16+DU16+EL16 | EU16: =U16+AE16+AO16+AY16+BI16+BS16+CC16+CM16+CW16+DG16+DW16+EN16 | EV16: - | EW16: =IFERROR((EL16-DU16)/DU16,"-") | EX16: =IFERROR((EN16-DW16)/DW16,"-") | EY16: =IFERROR((EO16-DX16)/DX16,"-")
... A19: Retirement Fund | B19: Solution Oriented Schemes | C19: Open ended Schemes | D19: Equity | E19: Equity | F19: Active Equity (incl Hybrid) | K19: =IF(OR(I19="",J19=""),"",I19-J19) | L19: 29104.498 | M19: 28388.195 | P19: - | Q19: 29 | R19: 2999887 | S19: 254.96061 | T19: 178.95675 | U19: 76.003861 | V19: 29996.207 | W19: 29245.262 | X19: 0 | Y19: 0 | Z19: - | AA19: 29 | AB19: 3003234 | AC19: 251.43797 | AD19: 198.5286 | AE19: 52.909369 | AF19: 31006.982 | AG19: 30588.372 | AH19: 0 | AI19: 0 | AJ19: - | AK19: 29 | AL19: 3009203 | AM19: 271.58925 | AN19: 193.11502 | AO19: 78.474223 | AP19: 31973.265 | AQ19: 31446.293 | AR19: 0 | AS19: 0 | AT19: - | AU19: 29 | AV19: 3016170 | AW19: 316.2963 | AX19: 197.39611 | AY19: 118.9002 | AZ19: 31415.747 | BA19: 31812.873 | BB19: 0 | BC19: 0 | BD19: - | BE19: 29 | BF19: 3022062 | BG19: 274.72057 | BH19: 140.24966 | BI19: 134.47092 | BJ19: 31058.435 | BK19: 31359.242 | BL19: 0 | BM19: 0 | BN19: - | BO19: 29 | BP19: 3027172 | BQ19: 291.37091 | BR19: 194.55248 | BS19: 96.818428 | BT19: 31454.415 | BU19: 31800.743 | BV19: 0 | BW19: 0 | BX19: - | BY19: 29 | BZ19: 3032112 | CA19: 274.53561 | CB19: 170.50777 | CC19: 104.02784 | CD19: 32512.298 | CE19: 32307.958 | CF19: 0 | CG19: 0 | CH19: - | CI19: 29 | CJ19: 3037674 | CK19: 268.39014 | CL19: 162.00462 | CM19: 106.38552 | CN19: 32835.333 | CO19: 32694.491 | CP19: 0 | CQ19: 0 | CR19: - | CS19: 29 | CT19: 3042915 | CU19: 299.89411 | CV19: 178.89782 | CW19: 120.99629 | CX19: 32828.506 | CY19: 32711.556 | CZ19: 0 | DA19: 0 | DB19: - | DC19: 29 | DD19: 3049871 | DE19: 279.23073 | DF19: 174.71369 | DG19: 104.51704 | DH19: 32044.113 | DI19: 32448.643 | DJ19: 0 | DK19: 0 | DL19: - | DM19: =S19+AC19+AM19+AW19+BG19+BQ19+CA19+CK19+CU19+DE19 | DN19: =U19+AE19+AO19+AY19+BI19+BS19+CC19+CM19+CW19+DG19 | DO19: - | DP19: =IFERROR((DE19-CU19)/CU19,"-") | DQ19: =IFERROR((DG19-CW19)/CW19,"-") | DR19: =IFERROR((DH19-CX19)/CX19,"-") | DS19: 29 | DT19: 3055597 | DU19: 293.78622 | DV19: 275.41609 | DW19: 18.370133 | DX19: 32229.114 | DY19: 32619.675 | DZ19: 0 | EA19: 0 | EB19: - | EC19: =S19+AC19+AM19+AW19+BG19+BQ19+CA19+CK19+CU19+DE19+DU19 | ED19: =U19+AE19+AO19+AY19+BI19+BS19+CC19+CM19+CW19+DG19+DW19 | EE19: - | EF19: =IFERROR((DU19-DE19)/DE19,"-") | EG19: =IFERROR((DW19-DG19)/DG19,"-") | EH19: =IFERROR((DX19-DH19)/DH19,"-") | EI19: - | EJ19: 29 | EK19: 3059924 | EL19: 252.81952 | EM19: 224.12636 | EN19: 28.693163 | EO19: 29275.013 | EP19: 30709.12 | EQ19: 0 | ER19: 0 | ES19: - | ET19: =S19+AC19+AM19+AW19+BG19+BQ19+CA19+CK19+CU19+DE19+DU19+EL19 | EU19: =U19+AE19+AO19+AY19+BI19+BS19+CC19+CM19+CW19+DG19+DW19+EN19 | EV19: - | EW19: =IFERROR((EL19-DU19)/DU19,"-") | EX19: =IFERROR((EN19-DW19)/DW19,"-") | EY19: =IFERROR((EO19-DX19)/DX19,"-")
A20: Other Equity Schemes | B20: Growth/Equity Oriented Schemes | C20: Close Ended Schemes | D20: Equity | E20: Equity | F20: Active Equity (incl Hybrid) | K20: =IF(OR(I20="",J20=""),"",I20-J20) | L20: 0 | M20: 0 | P20: - | Q20: 0 | R20: 0 | S20: 0 | T20: 0 | U20: 0 | V20: 0 | W20: 0 | X20: 0 | Y20: 0 | Z20: - | AA20: 0 | AB20: 0 | AC20: 0 | AD20: 0 | AE20: 0 | AF20: 0 | AG20: 0 | AH20: 0 | AI20: 0 | AJ20: - | AK20: 0 | AL20: 0 | AM20: 0 | AN20: 0 | AO20: 0 | AP20: 0 | AQ20: 0 | AR20: 0 | AS20: 0 | AT20: - | AU20: 0 | AV20: 0 | AW20: 0 | AX20: 0 | AY20: 0 | AZ20: 0 | BA20: 0 | BB20: 0 | BC20: 0 | BD20: - | BE20: 0 | BF20: 0 | BG20: 0 | BH20: 0 | BI20: 0 | BJ20: 0 | BK20: 0 | BL20: 0 | BM20: 0 | BN20: - | BO20: 0 | BP20: 0 | BQ20: 0 | BR20: 0 | BS20: 0 | BT20: 0 | BU20: 0 | BV20: 0 | BW20: 0 | BX20: - | BY20: 0 | BZ20: 0 | CA20: 0 | CB20: 0 | CC20: 0 | CD20: 0 | CE20: 0 | CF20: 0 | CG20: 0 | CH20: - | CI20: 0 | CJ20: 0 | CK20: 0 | CL20: 0 | CM20: 0 | CN20: 0 | CO20: 0 | CP20: 0 | CQ20: 0 | CR20: - | CS20: 0 | CT20: 0 | CU20: 0 | CV20: 0 | CW20: 0 | CX20: 0 | CY20: 0 | CZ20: 0 | DA20: 0 | DB20: - | DC20: 0 | DD20: 0 | DE20: 0 | DF20: 0 | DG20: 0 | DH20: 0 | DI20: 0 | DJ20: 0 | DK20: 0 | DL20: - | DM20: =S20+AC20+AM20+AW20+BG20+BQ20+CA20+CK20+CU20+DE20 | DN20: =U20+AE20+AO20+AY20+BI20+BS20+CC20+CM20+CW20+DG20 | DO20: - | DP20: - | DQ20: - | DR20: - | DS20: 0 | DT20: 0 | DU20: 0 | DV20: 0 | DW20: 0 | DX20: 0 | DY20: 0 | DZ20: 0 | EA20: 0 | EB20: - | EC20: =S20+AC20+AM20+AW20+BG20+BQ20+CA20+CK20+CU20+DE20+DU20 | ED20: =U20+AE20+AO20+AY20+BI20+BS20+CC20+CM20+CW20+DG20+DW20 | EE20: - | EF20: =IFERROR((DU20-DE20)/DE20,"-") | EG20: =IFERROR((DW20-DG20)/DG20,"-") | EH20: =IFERROR((DX20-DH20)/DH20,"-") | EI20: - | EJ20: 0 | EK20: 0 | EL20: 0 | EM20: 0 | EN20: 0 | EO20: 0 | EP20: 0 | EQ20: 0 | ER20: 0 | ES20: - | ET20: =S20+AC20+AM20+AW20+BG20+BQ20+CA20+CK20+CU20+DE20+DU20+EL20 | EU20: =U20+AE20+AO20+AY20+BI20+BS20+CC20+CM20+CW20+DG20+DW20+EN20 | EV20: - | EW20: =IFERROR((EL20-DU20)/DU20,"-") | EX20: =IFERROR((EN20-DW20)/DW20,"-") | EY20: =IFERROR((EO20-DX20)/DX20,"-")
A21: Other Schemes | B21: Other Schemes | C21: Close Ended Schemes | D21: Equity | E21: Equity | F21: Active Equity (incl Hybrid) | K21: =IF(OR(I21="",J21=""),"",I21-J21) | L21: 0 | M21: 0 | P21: - | Q21: 0 | R21: 0 | S21: 0 | T21: 0 | U21: 0 | V21: 0 | W21: 0 | X21: 0 | Y21: 0 | Z21: - | AA21: 0 | AB21: 0 | AC21: 0 | AD21: 0 | AE21: 0 | AF21: 0 | AG21: 0 | AH21: 0 | AI21: 0 | AJ21: - | AK21: 0 | AL21: 0 | AM21: 0 | AN21: 0 | AO21: 0 | AP21: 0 | AQ21: 0 | AR21: 0 | AS21: 0 | AT21: - | AU21: 0 | AV21: 0 | AW21: 0 | AX21: 0 | AY21: 0 | AZ21: 0 | BA21: 0 | BB21: 0 | BC21: 0 | BD21: - | BE21: 0 | BF21: 0 | BG21: 0 | BH21: 0 | BI21: 0 | BJ21: 0 | BK21: 0 | BL21: 0 | BM21: 0 | BN21: - | BO21: 0 | BP21: 0 | BQ21: 0 | BR21: 0 | BS21: 0 | BT21: 0 | BU21: 0 | BV21: 0 | BW21: 0 | BX21: - | BY21: 0 | BZ21: 0 | CA21: 0 | CB21: 0 | CC21: 0 | CD21: 0 | CE21: 0 | CF21: 0 | CG21: 0 | CH21: - | CI21: 0 | CJ21: 0 | CK21: 0 | CL21: 0 | CM21: 0 | CN21: 0 | CO21: 0 | CP21: 0 | CQ21: 0 | CR21: - | CS21: 0 | CT21: 0 | CU21: 0 | CV21: 0 | CW21: 0 | CX21: 0 | CY21: 0 | CZ21: 0 | DA21: 0 | DB21: - | DC21: 0 | DD21: 0 | DE21: 0 | DF21: 0 | DG21: 0 | DH21: 0 | DI21: 0 | DJ21: 0 | DK21: 0 | DL21: - | DM21: =S21+AC21+AM21+AW21+BG21+BQ21+CA21+CK21+CU21+DE21 | DN21: =U21+AE21+AO21+AY21+BI21+BS21+CC21+CM21+CW21+DG21 | DO21: - | DP21: 0 | DQ21: 0 | DR21: 0 | DS21: 0 | DT21: 0 | DU21: 0 | DV21: 0 | DW21: 0 | DX21: 0 | DY21: 0 | DZ21: 0 | EA21: 0 | EB21: - | EC21: =S21+AC21+AM21+AW21+BG21+BQ21+CA21+CK21+CU21+DE21+DU21 | ED21: =U21+AE21+AO21+AY21+BI21+BS21+CC21+CM21+CW21+DG21+DW21 | EE21: - | EF21: =IFERROR((DU21-DE21)/DE21,"-") | EG21: =IFERROR((DW21-DG21)/DG21,"-") | EH21: =IFERROR((DX21-DH21)/DH21,"-") | EI21: - | EJ21: 0 | EK21: 0 | EL21: 0 | EM21: 0 | EN21: 0 | EO21: 0 | EP21: 0 | EQ21: 0 | ER21: 0 | ES21: - | ET21: =S21+AC21+AM21+AW21+BG21+BQ21+CA21+CK21+CU21+DE21+DU21+EL21 | EU21: =U21+AE21+AO21+AY21+BI21+BS21+CC21+CM21+CW21+DG21+DW21+EN21 | EV21: - | EW21: =IFERROR((EL21-DU21)/DU21,"-") | EX21: =IFERROR((EN21-DW21)/DW21,"-") | EY21: =IFERROR((EO21-DX21)/DX21,"-")
A22: Other Schemes | B22: Interval Schemes | C22: - | D22: - | E22: - | F22: Active Equity (incl Hybrid) | K22: =IF(OR(I22="",J22=""),"",I22-J22) | L22: 0 | M22: 0 | P22: - | Q22: 0 | R22: 0 | S22: 0 | T22: 0 | U22: 0 | V22: 0 | W22: 0 | X22: 0 | Y22: 0 | Z22: - | AA22: 0 | AB22: 0 | AC22: 0 | AD22: 0 | AE22: 0 | AF22: 0 | AG22: 0 | AH22: 0 | AI22: 0 | AJ22: - | AK22: 0 | AL22: 0 | AM22: 0 | AN22: 0 | AO22: 0 | AP22: 0 | AQ22: 0 | AR22: 0 | AS22: 0 | AT22: - | AU22: 0 | AV22: 0 | AW22: 0 | AX22: 0 | AY22: 0 | AZ22: 0 | BA22: 0 | BB22: 0 | BC22: 0 | BD22: - | BE22: 0 | BF22: 0 | BG22: 0 | BH22: 0 | BI22: 0 | BJ22: 0 | BK22: 0 | BL22: 0 | BM22: 0 | BN22: - | BO22: 0 | BP22: 0 | BQ22: 0 | BR22: 0 | BS22: 0 | BT22: 0 | BU22: 0 | BV22: 0 | BW22: 0 | BX22: - | BY22: 0 | BZ22: 0 | CA22: 0 | CB22: 0 | CC22: 0 | CD22: 0 | CE22: 0 | CF22: 0 | CG22: 0 | CH22: - | CI22: 0 | CJ22: 0 | CK22: 0 | CL22: 0 | CM22: 0 | CN22: 0 | CO22: 0 | CP22: 0 | CQ22: 0 | CR22: - | CS22: 0 | CT22: 0 | CU22: 0 | CV22: 0 | CW22: 0 | CX22: 0 | CY22: 0 | CZ22: 0 | DA22: 0 | DB22: - | DC22: 0 | DD22: 0 | DE22: 0 | DF22: 0 | DG22: 0 | DH22: 0 | DI22: 0 | DJ22: 0 | DK22: 0 | DL22: - | DM22: =S22+AC22+AM22+AW22+BG22+BQ22+CA22+CK22+CU22+DE22 | DN22: =U22+AE22+AO22+AY22+BI22+BS22+CC22+CM22+CW22+DG22 | DO22: - | DP22: 0 | DQ22: 0 | DR22: 0 | DS22: 0 | DT22: 0 | DU22: 0 | DV22: 0 | DW22: 0 | DX22: 0 | DY22: 0 | DZ22: 0 | EA22: 0 | EB22: - | EC22: =S22+AC22+AM22+AW22+BG22+BQ22+CA22+CK22+CU22+DE22+DU22 | ED22: =U22+AE22+AO22+AY22+BI22+BS22+CC22+CM22+CW22+DG22+DW22 | EE22: - | EF22: =IFERROR((DU22-DE22)/DE22,"-") | EG22: =IFERROR((DW22-DG22)/DG22,"-") | EH22: =IFERROR((DX22-DH22)/DH22,"-") | EI22: - | EJ22: 0 | EK22: 0 | EL22: 0 | EM22: 0 | EN22: 0 | EO22: 0 | EP22: 0 | EQ22: 0 | ER22: 0 | ES22: - | ET22: =S22+AC22+AM22+AW22+BG22+BQ22+CA22+CK22+CU22+DE22+DU22+EL22 | EU22: =U22+AE22+AO22+AY22+BI22+BS22+CC22+CM22+CW22+DG22+DW22+EN22 | EV22: - | EW22: =IFERROR((EL22-DU22)/DU22,"-") | EX22: =IFERROR((EN22-DW22)/DW22,"-") | EY22: =IFERROR((EO22-DX22)/DX22,"-")
A23: ELSS-Close Ended | B23: Growth/Equity Oriented Schemes | C23: Close Ended Schemes | D23: Equity | E23: Equity | F23: Active Equity (incl Hybrid) | K23: =IF(OR(I23="",J23=""),"",I23-J23) | L23: 4034.5205 | M23: 3977.8897 | P23: - | Q23: 15 | R23: 258637 | S23: 0 | T23: 15.599505 | U23: -15.599505 | V23: 4174.2777 | W23: 4052.9507 | X23: 0 | Y23: 0 | Z23: - | AA23: 15 | AB23: 257771 | AC23: 0 | AD23: 18.563769 | AE23: -18.563769 | AF23: 4272.9353 | AG23: 4227.2002 | AH23: 0 | AI23: 0 | AJ23: - | AK23: 15 | AL23: 256846 | AM23: 0 | AN23: 19.118207 | AO23: -19.118207 | AP23: 4398.6399 | AQ23: 4324.4088 | AR23: 0 | AS23: 0 | AT23: - | AU23: 15 | AV23: 255907 | AW23: 0 | AX23: 29.724395 | AY23: -29.724395 | AZ23: 4275.5324 | BA23: 4342.108 | BB23: 0 | BC23: 0 | BD23: - | BE23: 15 | BF23: 255243 | BG23: 0 | BH23: 13.0443 | BI23: -13.0443 | BJ23: 4219.1556 | BK23: 4244.9541 | BL23: 0 | BM23: 0 | BN23: - | BO23: 15 | BP23: 254488 | BQ23: 0 | BR23: 16.916785 | BS23: -16.916785 | BT23: 4230.7822 | BU23: 4297.0679 | BV23: 0 | BW23: 0 | BX23: - | BY23: 15 | BZ23: 253748 | CA23: 0 | CB23: 18.716928 | CC23: -18.716928 | CD23: 4346.9907 | CE23: 4332.3777 | CF23: 0 | CG23: 0 | CH23: - | CI23: 15 | CJ23: 252978 | CK23: 0 | CL23: 17.437278 | CM23: -17.437278 | CN23: 4370.847 | CO23: 4347.76 | CP23: 0 | CQ23: 0 | CR23: - | CS23: 15 | CT23: 252071 | CU23: 0 | CV23: 19.251978 | CW23: -19.251978 | CX23: 4342.8818 | CY23: 4334.9311 | CZ23: 0 | DA23: 0 | DB23: - | DC23: 15 | DD23: 251406 | DE23: 0 | DF23: 15.424995 | DG23: -15.424995 | DH23: 4196.2202 | DI23: 4258.5084 | DJ23: 0 | DK23: 0 | DL23: - | DM23: =S23+AC23+AM23+AW23+BG23+BQ23+CA23+CK23+CU23+DE23 | DN23: =U23+AE23+AO23+AY23+BI23+BS23+CC23+CM23+CW23+DG23 | DO23: - | DP23: 0 | DQ23: =IFERROR((DG23-CW23)/CW23,"-") | DR23: =IFERROR((DH23-CX23)/CX23,"-") | DS23: 15 | DT23: 250763 | DU23: 0 | DV23: 12.836447 | DW23: -12.836447 | DX23: 4153.951 | DY23: 4220.3996 | DZ23: 0 | EA23: 0 | EB23: - | EC23: =S23+AC23+AM23+AW23+BG23+BQ23+CA23+CK23+CU23+DE23+DU23 | ED23: =U23+AE23+AO23+AY23+BI23+BS23+CC23+CM23+CW23+DG23+DW23 | EE23: - | EF23: =IFERROR((DU23-DE23)/DE23,"-") | EG23: =IFERROR((DW23-DG23)/DG23,"-") | EH23: =IFERROR((DX23-DH23)/DH23,"-") | EI23: - | EJ23: 13 | EK23: 247165 | EL23: 0 | EM23: 84.294009 | EN23: -84.294009 | EO23: 3558.3566 | EP23: 3868.1608 | EQ23: - | ER23: - | ES23: - | ET23: =S23+AC23+AM23+AW23+BG23+BQ23+CA23+CK23+CU23+DE23+DU23+EL23 | EU23: =U23+AE23+AO23+AY23+BI23+BS23+CC23+CM23+CW23+DG23+DW23+EN23 | EV23: - | EW23: =IFERROR((EL23-DU23)/DU23,"-") | EX23: =IFERROR((EN23-DW23)/DW23,"-") | EY23: =IFERROR((EO23-DX23)/DX23,"-")
